> initializing model parallel with size 1
> initializing ddp with size 1
> initializing pipeline with size 1
The model weights are not tied. Please use the `tie_weights` method before using the `infer_auto_device` function.
Loading checkpoint shards:   0%|          | 0/3 [00:00<?, ?it/s]Loading checkpoint shards:  33%|███▎      | 1/3 [08:23<16:47, 503.55s/it]ERROR:torch.distributed.elastic.multiprocessing.api:failed (exitcode: -15) local_rank: 0 (pid: 1191880) of binary: /home/zhihanliu/anaconda3/envs/shuqi/bin/python
Traceback (most recent call last):
  File "/home/zhihanliu/anaconda3/envs/shuqi/lib/python3.9/runpy.py", line 197, in _run_module_as_main
    return _run_code(code, main_globals, None,
  File "/home/zhihanliu/anaconda3/envs/shuqi/lib/python3.9/runpy.py", line 87, in _run_code
    exec(code, run_globals)
  File "/home/zhihanliu/anaconda3/envs/shuqi/lib/python3.9/site-packages/torch/distributed/run.py", line 798, in <module>
    main()
  File "/home/zhihanliu/anaconda3/envs/shuqi/lib/python3.9/site-packages/torch/distributed/elastic/multiprocessing/errors/__init__.py", line 346, in wrapper
    return f(*args, **kwargs)
  File "/home/zhihanliu/anaconda3/envs/shuqi/lib/python3.9/site-packages/torch/distributed/run.py", line 794, in main
    run(args)
  File "/home/zhihanliu/anaconda3/envs/shuqi/lib/python3.9/site-packages/torch/distributed/run.py", line 785, in run
    elastic_launch(
  File "/home/zhihanliu/anaconda3/envs/shuqi/lib/python3.9/site-packages/torch/distributed/launcher/api.py", line 134, in __call__
    return launch_agent(self._config, self._entrypoint, list(args))
  File "/home/zhihanliu/anaconda3/envs/shuqi/lib/python3.9/site-packages/torch/distributed/launcher/api.py", line 250, in launch_agent
    raise ChildFailedError(
torch.distributed.elastic.multiprocessing.errors.ChildFailedError: 
=========================================================
run_planning.py FAILED
---------------------------------------------------------
Failures:
  <NO_OTHER_FAILURES>
---------------------------------------------------------
Root Cause (first observed failure):
[0]:
  time      : 2023-09-05_18:26:32
  host      : nebula.osl.northwestern.edu
  rank      : 0 (local_rank: 0)
  exitcode  : -15 (pid: 1191880)
  error_file: <N/A>
  traceback : Signal 15 (SIGTERM) received by PID 1191880
=========================================================
